Workbook

Sheet Cover
B2: MYATLASTIC
B3: Interactive World Geography App — Financial Model
B5: Monetisation: Tight free (10 countries preview) + School B2B
B7: Model period: | C7: 36 months
B8: Base currency: | C8: USD ($)
B9: Scenario selector: | C9: Base | D9: ← Bear / Base / Bull
B11: Sheet map:
B12: Assumptions | C12: Drivers — edit here
B13: Users | C13: User waterfall: installs, conversion, churn
B14: Revenue | C14: Revenue by stream
B15: Costs | C15: OPEX, COGS, marketing
B16: P&L | C16: Monthly P&L + cumulative cash
B17: Summary | C17: Executive summary + KPIs
B20: Tight-free rationale:
B21: Hard paywall at country #11. Higher per-user conversion (forced trigger),
B22: smaller pool than generous-free, weaker virality.
B23: Founder override applied vs. model recommendation.
B25: Colour key:
B26: Hardcoded input
B27: Formula
B28: Cross-sheet link
B29: Key assumption

Sheet Assumptions
A1: ASSUMPTIONS — TIGHT FREE (USD)
A3: SCENARIO TABLE
A4: Driver | B4: Bear | C4: Base | D4: Bull | E4: Active
A6: USER ACQUISITION
A7: M1 organic installs | B7: 150 | C7: 350 | D7: 1000 | E7: =CHOOSE(MATCH(Cover!$C$9,{"Bear","Base","Bull"},0),B7,C7,D7)
A8: Monthly organic growth | B8: 0.03 | C8: 0.08 | D8: 0.14 | E8: =CHOOSE(MATCH(Cover!$C$9,{"Bear","Base","Bull"},0),B8,C8,D8)
A9: Monthly paid spend ($) | B9: 0 | C9: 650 | D9: 2600 | E9: =CHOOSE(MATCH(Cover!$C$9,{"Bear","Base","Bull"},0),B9,C9,D9)
A10: Cost per install paid ($) | B10: 5.5 | C10: 4 | D10: 2.8 | E10: =CHOOSE(MATCH(Cover!$C$9,{"Bear","Base","Bull"},0),B10,C10,D10)
A11: Viral k-factor | B11: 0.02 | C11: 0.05 | D11: 0.1 | E11: =CHOOSE(MATCH(Cover!$C$9,{"Bear","Base","Bull"},0),B11,C11,D11)
A13: CONVERSION & RETENTION
A14: Free to paid conversion | B14: 0.03 | C14: 0.055 | D14: 0.085 | E14: =CHOOSE(MATCH(Cover!$C$9,{"Bear","Base","Bull"},0),B14,C14,D14)
A15: Months to convert (avg) | B15: 2 | C15: 1 | D15: 1 | E15: =CHOOSE(MATCH(Cover!$C$9,{"Bear","Base","Bull"},0),B15,C15,D15)
A16: Monthly subscriber churn | B16: 0.1 | C16: 0.07 | D16: 0.05 | E16: =CHOOSE(MATCH(Cover!$C$9,{"Bear","Base","Bull"},0),B16,C16,D16)
A17: Free user monthly churn | B17: 0.4 | C17: 0.3 | D17: 0.22 | E17: =CHOOSE(MATCH(Cover!$C$9,{"Bear","Base","Bull"},0),B17,C17,D17)
A18: Pct on annual plan | B18: 0.4 | C18: 0.55 | D18: 0.7 | E18: =CHOOSE(MATCH(Cover!$C$9,{"Bear","Base","Bull"},0),B18,C18,D18)
A19: Pct on family plan | B19: 0.1 | C19: 0.2 | D19: 0.35 | E19: =CHOOSE(MATCH(Cover!$C$9,{"Bear","Base","Bull"},0),B19,C19,D19)
A21: PRICING
A22: Monthly sub ($) | B22: 3.99 | C22: 7.99 | D22: 9.99 | E22: =CHOOSE(MATCH(Cover!$C$9,{"Bear","Base","Bull"},0),B22,C22,D22)
A23: Annual sub ($) | B23: 24.99 | C23: 29.99 | D23: 39.99 | E23: =CHOOSE(MATCH(Cover!$C$9,{"Bear","Base","Bull"},0),B23,C23,D23)
A24: Family annual ($) | B24: 39.99 | C24: 49.99 | D24: 59.99 | E24: =CHOOSE(MATCH(Cover!$C$9,{"Bear","Base","Bull"},0),B24,C24,D24)
A25: School annual ($) | B25: 129 | C25: 199 | D25: 329 | E25: =CHOOSE(MATCH(Cover!$C$9,{"Bear","Base","Bull"},0),B25,C25,D25)
A27: SCHOOL B2B (starts M7)
A28: Schools by M12 | B28: 0 | C28: 6 | D28: 20 | E28: =CHOOSE(MATCH(Cover!$C$9,{"Bear","Base","Bull"},0),B28,C28,D28)
A29: Schools by M24 | B29: 4 | C29: 30 | D29: 110 | E29: =CHOOSE(MATCH(Cover!$C$9,{"Bear","Base","Bull"},0),B29,C29,D29)
A30: Schools by M36 | B30: 12 | C30: 90 | D30: 300 | E30: =CHOOSE(MATCH(Cover!$C$9,{"Bear","Base","Bull"},0),B30,C30,D30)
A31: School annual churn | B31: 0.2 | C31: 0.1 | D31: 0.05 | E31: =CHOOSE(MATCH(Cover!$C$9,{"Bear","Base","Bull"},0),B31,C31,D31)
A33: PLATFORM FEES
A34: App Store fee (Y1) | B34: 0.15 | C34: 0.15 | D34: 0.15 | E34: =CHOOSE(MATCH(Cover!$C$9,{"Bear","Base","Bull"},0),B34,C34,D34)
A35: Stripe fee (school) | B35: 0.029 | C35: 0.029 | D35: 0.029 | E35: =CHOOSE(MATCH(Cover!$C$9,{"Bear","Base","Bull"},0),B35,C35,D35)
A36: Hosting per 1000 MAU ($) | B36: 1 | C36: 0.65 | D36: 0.4 | E36: =CHOOSE(MATCH(Cover!$C$9,{"Bear","Base","Bull"},0),B36,C36,D36)
A37: Content licence /mo ($) | B37: 250 | C37: 130 | D37: 65 | E37: =CHOOSE(MATCH(Cover!$C$9,{"Bear","Base","Bull"},0),B37,C37,D37)
A39: FIXED OPEX (monthly USD)
A40: Founder salary | B40: 0 | C40: 3250 | D40: 6500 | E40: =CHOOSE(MATCH(Cover!$C$9,{"Bear","Base","Bull"},0),B40,C40,D40)
A41: Contractors | B41: 650 | C41: 1950 | D41: 5200 | E41: =CHOOSE(MATCH(Cover!$C$9,{"Bear","Base","Bull"},0),B41,C41,D41)
A42: Tools & subs | B42: 130 | C42: 260 | D42: 520 | E42: =CHOOSE(MATCH(Cover!$C$9,{"Bear","Base","Bull"},0),B42,C42,D42)
A43: Legal/compliance | B43: 130 | C43: 390 | D43: 780 | E43: =CHOOSE(MATCH(Cover!$C$9,{"Bear","Base","Bull"},0),B43,C43,D43)
A44: Insurance & misc | B44: 65 | C44: 195 | D44: 390 | E44: =CHOOSE(MATCH(Cover!$C$9,{"Bear","Base","Bull"},0),B44,C44,D44)
A46: ONE-OFF COSTS (M1)
A47: App dev | B47: 6500 | C47: 19500 | D47: 52000 | E47: =CHOOSE(MATCH(Cover!$C$9,{"Bear","Base","Bull"},0),B47,C47,D47)
A48: Content production | B48: 1300 | C48: 3900 | D48: 10400 | E48: =CHOOSE(MATCH(Cover!$C$9,{"Bear","Base","Bull"},0),B48,C48,D48)
...

Sheet Users
A1: USER WATERFALL
A3: Metric | B3: M1 | C3: M2 | D3: M3 | E3: M4 | F3: M5 | G3: M6 | H3: M7 | I3: M8 | J3: M9 | K3: M10 | L3: M11 | M3: M12 | N3: M13 | O3: M14 | P3: M15 | Q3: M16 | R3: M17 | S3: M18 | T3: M19 | U3: M20 | V3: M21 | W3: M22 | X3: M23 | Y3: M24 | Z3: M25 | AA3: M26 | AB3: M27 | AC3: M28 | AD3: M29 | AE3: M30 | AF3: M31 | AG3: M32 | AH3: M33 | AI3: M34 | AJ3: M35 | AK3: M36
A4: New organic installs | B4: =Assumptions!E7 | C4: =B4*(1+Assumptions!$E$8) | D4: =C4*(1+Assumptions!$E$8) | E4: =D4*(1+Assumptions!$E$8) | F4: =E4*(1+Assumptions!$E$8) | G4: =F4*(1+Assumptions!$E$8) | H4: =G4*(1+Assumptions!$E$8) | I4: =H4*(1+Assumptions!$E$8) | J4: =I4*(1+Assumptions!$E$8) | ... AK4: =AJ4*(1+Assumptions!$E$8)
A5: New paid installs | B5: =IF(1<3,0,IFERROR(Assumptions!$E$9/Assumptions!$E$10,0)) | C5: =IF(2<3,0,IFERROR(Assumptions!$E$9/Assumptions!$E$10,0)) | D5: =IF(3<3,0,IFERROR(Assumptions!$E$9/Assumptions!$E$10,0)) | E5: =IF(4<3,0,IFERROR(Assumptions!$E$9/Assumptions!$E$10,0)) | F5: =IF(5<3,0,IFERROR(Assumptions!$E$9/Assumptions!$E$10,0)) | G5: =IF(6<3,0,IFERROR(Assumptions!$E$9/Assumptions!$E$10,0)) | H5: =IF(7<3,0,IFERROR(Assumptions!$E$9/Assumptions!$E$10,0)) | I5: =IF(8<3,0,IFERROR(Assumptions!$E$9/Assumptions!$E$10,0)) | J5: =IF(9<3,0,IFERROR(Assumptions!$E$9/Assumptions!$E$10,0)) | K5: =IF(10<3,0,IFERROR(Assumptions!$E$9/Assumptions!$E$10,0)) | L5: =IF(11<3,0,IFERROR(Assumptions!$E$9/Assumptions!$E$10,0)) | M5: =IF(12<3,0,IFERROR(Assumptions!$E$9/Assumptions!$E$10,0)) | N5: =IF(13<3,0,IFERROR(Assumptions!$E$9/Assumptions!$E$10,0)) | O5: =IF(14<3,0,IFERROR(Assumptions!$E$9/Assumptions!$E$10,0)) | P5: =IF(15<3,0,IFERROR(Assumptions!$E$9/Assumptions!$E$10,0)) | Q5: =IF(16<3,0,IFERROR(Assumptions!$E$9/Assumptions!$E$10,0)) | R5: =IF(17<3,0,IFERROR(Assumptions!$E$9/Assumptions!$E$10,0)) | S5: =IF(18<3,0,IFERROR(Assumptions!$E$9/Assumptions!$E$10,0)) | T5: =IF(19<3,0,IFERROR(Assumptions!$E$9/Assumptions!$E$10,0)) | U5: =IF(20<3,0,IFERROR(Assumptions!$E$9/Assumptions!$E$10,0)) | V5: =IF(21<3,0,IFERROR(Assumptions!$E$9/Assumptions!$E$10,0)) | W5: =IF(22<3,0,IFERROR(Assumptions!$E$9/Assumptions!$E$10,0)) | X5: =IF(23<3,0,IFERROR(Assumptions!$E$9/Assumptions!$E$10,0)) | Y5: =IF(24<3,0,IFERROR(Assumptions!$E$9/Assumptions!$E$10,0)) | Z5: =IF(25<3,0,IFERROR(Assumptions!$E$9/Assumptions!$E$10,0)) | AA5: =IF(26<3,0,IFERROR(Assumptions!$E$9/Assumptions!$E$10,0)) | AB5: =IF(27<3,0,IFERROR(Assumptions!$E$9/Assumptions!$E$10,0)) | AC5: =IF(28<3,0,IFERROR(Assumptions!$E$9/Assumptions!$E$10,0)) | AD5: =IF(29<3,0,IFERROR(Assumptions!$E$9/Assumptions!$E$10,0)) | AE5: =IF(30<3,0,IFERROR(Assumptions!$E$9/Assumptions!$E$10,0)) | AF5: =IF(31<3,0,IFERROR(Assumptions!$E$9/Assumptions!$E$10,0)) | AG5: =IF(32<3,0,IFERROR(Assumptions!$E$9/Assumptions!$E$10,0)) | AH5: =IF(33<3,0,IFERROR(Assumptions!$E$9/Assumptions!$E$10,0)) | AI5: =IF(34<3,0,IFERROR(Assumptions!$E$9/Assumptions!$E$10,0)) | AJ5: =IF(35<3,0,IFERROR(Assumptions!$E$9/Assumptions!$E$10,0)) | AK5: =IF(36<3,0,IFERROR(Assumptions!$E$9/Assumptions!$E$10,0))
A6: Viral installs | B6: 0 | C6: =(B4+B5)*Assumptions!$E$11 | D6: =(C4+C5)*Assumptions!$E$11 | E6: =(D4+D5)*Assumptions!$E$11 | F6: =(E4+E5)*Assumptions!$E$11 | G6: =(F4+F5)*Assumptions!$E$11 | H6: =(G4+G5)*Assumptions!$E$11 | I6: =(H4+H5)*Assumptions!$E$11 | J6: =(I4+I5)*Assumptions!$E$11 | ... AK6: =(AJ4+AJ5)*Assumptions!$E$11
A7: Total new installs | B7: =SUM(B4:B6) | C7: =SUM(C4:C6) | D7: =SUM(D4:D6) | E7: =SUM(E4:E6) | F7: =SUM(F4:F6) | G7: =SUM(G4:G6) | H7: =SUM(H4:H6) | I7: =SUM(I4:I6) | ... AK7: =SUM(AK4:AK6)
A9: Free users active | B9: =B7-B12 | C9: =(B9*(1-Assumptions!$E$17))+C7-C12 | D9: =(C9*(1-Assumptions!$E$17))+D7-D12 | E9: =(D9*(1-Assumptions!$E$17))+E7-E12 | F9: =(E9*(1-Assumptions!$E$17))+F7-F12 | G9: =(F9*(1-Assumptions!$E$17))+G7-G12 | H9: =(G9*(1-Assumptions!$E$17))+H7-H12 | I9: =(H9*(1-Assumptions!$E$17))+I7-I12 | J9: =(I9*(1-Assumptions!$E$17))+J7-J12 | ... AK9: =(AJ9*(1-Assumptions!$E$17))+AK7-AK12
A11: Conversion pool | B11: 0 | C11: =B9 | D11: =C9 | E11: =D9 | F11: =E9 | G11: =F9 | H11: =G9 | I11: =H9 | J11: =I9 | ... AK11: =AJ9
A12: New paid conversions | B12: =B11*Assumptions!$E$14 | C12: =C11*Assumptions!$E$14 | D12: =D11*Assumptions!$E$14 | E12: =E11*Assumptions!$E$14 | F12: =F11*Assumptions!$E$14 | G12: =G11*Assumptions!$E$14 | H12: =H11*Assumptions!$E$14 | I12: =I11*Assumptions!$E$14 | ... AK12: =AK11*Assumptions!$E$14
A14: Paid subscribers total | B14: =B12 | C14: =(B14*(1-Assumptions!$E$16))+C12 | D14: =(C14*(1-Assumptions!$E$16))+D12 | E14: =(D14*(1-Assumptions!$E$16))+E12 | F14: =(E14*(1-Assumptions!$E$16))+F12 | G14: =(F14*(1-Assumptions!$E$16))+G12 | H14: =(G14*(1-Assumptions!$E$16))+H12 | I14: =(H14*(1-Assumptions!$E$16))+I12 | J14: =(I14*(1-Assumptions!$E$16))+J12 | ... AK14: =(AJ14*(1-Assumptions!$E$16))+AK12
A15: on monthly plan | B15: =B14*(1-Assumptions!$E$18)*(1-Assumptions!$E$19) | C15: =C14*(1-Assumptions!$E$18)*(1-Assumptions!$E$19) | D15: =D14*(1-Assumptions!$E$18)*(1-Assumptions!$E$19) | E15: =E14*(1-Assumptions!$E$18)*(1-Assumptions!$E$19) | F15: =F14*(1-Assumptions!$E$18)*(1-Assumptions!$E$19) | G15: =G14*(1-Assumptions!$E$18)*(1-Assumptions!$E$19) | H15: =H14*(1-Assumptions!$E$18)*(1-Assumptions!$E$19) | I15: =I14*(1-Assumptions!$E$18)*(1-Assumptions!$E$19) | ... AK15: =AK14*(1-Assumptions!$E$18)*(1-Assumptions!$E$19)
A16: on annual plan | B16: =B14*Assumptions!$E$18*(1-Assumptions!$E$19) | C16: =C14*Assumptions!$E$18*(1-Assumptions!$E$19) | D16: =D14*Assumptions!$E$18*(1-Assumptions!$E$19) | E16: =E14*Assumptions!$E$18*(1-Assumptions!$E$19) | F16: =F14*Assumptions!$E$18*(1-Assumptions!$E$19) | G16: =G14*Assumptions!$E$18*(1-Assumptions!$E$19) | H16: =H14*Assumptions!$E$18*(1-Assumptions!$E$19) | I16: =I14*Assumptions!$E$18*(1-Assumptions!$E$19) | ... AK16: =AK14*Assumptions!$E$18*(1-Assumptions!$E$19)
A17: on family plan | B17: =B14*Assumptions!$E$19 | C17: =C14*Assumptions!$E$19 | D17: =D14*Assumptions!$E$19 | E17: =E14*Assumptions!$E$19 | F17: =F14*Assumptions!$E$19 | G17: =G14*Assumptions!$E$19 | H17: =H14*Assumptions!$E$19 | I17: =I14*Assumptions!$E$19 | ... AK17: =AK14*Assumptions!$E$19
A19: Schools cumulative | B19: 0 | C19: 0 | D19: 0 | E19: 0 | F19: 0 | G19: 0 | H19: =ROUND(Assumptions!$E$28*(7-6)/6,0) | I19: =ROUND(Assumptions!$E$28*(8-6)/6,0) | J19: =ROUND(Assumptions!$E$28*(9-6)/6,0) | K19: =ROUND(Assumptions!$E$28*(10-6)/6,0) | L19: =ROUND(Assumptions!$E$28*(11-6)/6,0) | M19: =ROUND(Assumptions!$E$28*(12-6)/6,0) | N19: =ROUND(Assumptions!$E$28+(Assumptions!$E$29-Assumptions!$E$28)*(13-12)/12,0) | O19: =ROUND(Assumptions!$E$28+(Assumptions!$E$29-Assumptions!$E$28)*(14-12)/12,0) | P19: =ROUND(Assumptions!$E$28+(Assumptions!$E$29-Assumptions!$E$28)*(15-12)/12,0) | Q19: =ROUND(Assumptions!$E$28+(Assumptions!$E$29-Assumptions!$E$28)*(16-12)/12,0) | R19: =ROUND(Assumptions!$E$28+(Assumptions!$E$29-Assumptions!$E$28)*(17-12)/12,0) | S19: =ROUND(Assumptions!$E$28+(Assumptions!$E$29-Assumptions!$E$28)*(18-12)/12,0) | T19: =ROUND(Assumptions!$E$28+(Assumptions!$E$29-Assumptions!$E$28)*(19-12)/12,0) | U19: =ROUND(Assumptions!$E$28+(Assumptions!$E$29-Assumptions!$E$28)*(20-12)/12,0) | V19: =ROUND(Assumptions!$E$28+(Assumptions!$E$29-Assumptions!$E$28)*(21-12)/12,0) | W19: =ROUND(Assumptions!$E$28+(Assumptions!$E$29-Assumptions!$E$28)*(22-12)/12,0) | X19: =ROUND(Assumptions!$E$28+(Assumptions!$E$29-Assumptions!$E$28)*(23-12)/12,0) | Y19: =ROUND(Assumptions!$E$28+(Assumptions!$E$29-Assumptions!$E$28)*(24-12)/12,0) | Z19: =ROUND(Assumptions!$E$29+(Assumptions!$E$30-Assumptions!$E$29)*(25-24)/12,0) | AA19: =ROUND(Assumptions!$E$29+(Assumptions!$E$30-Assumptions!$E$29)*(26-24)/12,0) | AB19: =ROUND(Assumptions!$E$29+(Assumptions!$E$30-Assumptions!$E$29)*(27-24)/12,0) | AC19: =ROUND(Assumptions!$E$29+(Assumptions!$E$30-Assumptions!$E$29)*(28-24)/12,0) | AD19: =ROUND(Assumptions!$E$29+(Assumptions!$E$30-Assumptions!$E$29)*(29-24)/12,0) | AE19: =ROUND(Assumptions!$E$29+(Assumptions!$E$30-Assumptions!$E$29)*(30-24)/12,0) | AF19: =ROUND(Assumptions!$E$29+(Assumptions!$E$30-Assumptions!$E$29)*(31-24)/12,0) | AG19: =ROUND(Assumptions!$E$29+(Assumptions!$E$30-Assumptions!$E$29)*(32-24)/12,0) | AH19: =ROUND(Assumptions!$E$29+(Assumptions!$E$30-Assumptions!$E$29)*(33-24)/12,0) | AI19: =ROUND(Assumptions!$E$29+(Assumptions!$E$30-Assumptions!$E$29)*(34-24)/12,0) | AJ19: =ROUND(Assumptions!$E$29+(Assumptions!$E$30-Assumptions!$E$29)*(35-24)/12,0) | AK19: =ROUND(Assumptions!$E$29+(Assumptions!$E$30-Assumptions!$E$29)*(36-24)/12,0)
A21: TOTAL USERS | B21: =B9+B14 | C21: =C9+C14 | D21: =D9+D14 | E21: =E9+E14 | F21: =F9+F14 | G21: =G9+G14 | H21: =H9+H14 | I21: =I9+I14 | ... AK21: =AK9+AK14

Sheet Revenue
A1: REVENUE (USD)
A3: Stream | B3: M1 | C3: M2 | D3: M3 | E3: M4 | F3: M5 | G3: M6 | H3: M7 | I3: M8 | J3: M9 | K3: M10 | L3: M11 | M3: M12 | N3: M13 | O3: M14 | P3: M15 | Q3: M16 | R3: M17 | S3: M18 | T3: M19 | U3: M20 | V3: M21 | W3: M22 | X3: M23 | Y3: M24 | Z3: M25 | AA3: M26 | AB3: M27 | AC3: M28 | AD3: M29 | AE3: M30 | AF3: M31 | AG3: M32 | AH3: M33 | AI3: M34 | AJ3: M35 | AK3: M36
A4: Monthly subscription | B4: =Users!B15*Assumptions!$E$22 | C4: =Users!C15*Assumptions!$E$22 | D4: =Users!D15*Assumptions!$E$22 | E4: =Users!E15*Assumptions!$E$22 | F4: =Users!F15*Assumptions!$E$22 | G4: =Users!G15*Assumptions!$E$22 | H4: =Users!H15*Assumptions!$E$22 | I4: =Users!I15*Assumptions!$E$22 | ... AK4: =Users!AK15*Assumptions!$E$22
A5: Annual sub (monthly recog) | B5: =Users!B16*Assumptions!$E$23/12 | C5: =Users!C16*Assumptions!$E$23/12 | D5: =Users!D16*Assumptions!$E$23/12 | E5: =Users!E16*Assumptions!$E$23/12 | F5: =Users!F16*Assumptions!$E$23/12 | G5: =Users!G16*Assumptions!$E$23/12 | H5: =Users!H16*Assumptions!$E$23/12 | I5: =Users!I16*Assumptions!$E$23/12 | ... AK5: =Users!AK16*Assumptions!$E$23/12
A6: Family plan | B6: =Users!B17*Assumptions!$E$24/12 | C6: =Users!C17*Assumptions!$E$24/12 | D6: =Users!D17*Assumptions!$E$24/12 | E6: =Users!E17*Assumptions!$E$24/12 | F6: =Users!F17*Assumptions!$E$24/12 | G6: =Users!G17*Assumptions!$E$24/12 | H6: =Users!H17*Assumptions!$E$24/12 | I6: =Users!I17*Assumptions!$E$24/12 | ... AK6: =Users!AK17*Assumptions!$E$24/12
A7: School B2B | B7: =Users!B19*Assumptions!$E$25/12 | C7: =Users!C19*Assumptions!$E$25/12 | D7: =Users!D19*Assumptions!$E$25/12 | E7: =Users!E19*Assumptions!$E$25/12 | F7: =Users!F19*Assumptions!$E$25/12 | G7: =Users!G19*Assumptions!$E$25/12 | H7: =Users!H19*Assumptions!$E$25/12 | I7: =Users!I19*Assumptions!$E$25/12 | ... AK7: =Users!AK19*Assumptions!$E$25/12
A9: GROSS REVENUE | B9: =SUM(B4:B7) | C9: =SUM(C4:C7) | D9: =SUM(D4:D7) | E9: =SUM(E4:E7) | F9: =SUM(F4:F7) | G9: =SUM(G4:G7) | H9: =SUM(H4:H7) | I9: =SUM(I4:I7) | ... AK9: =SUM(AK4:AK7)
A10: Less: App Store fees | B10: =-(B4+B5+B6)*Assumptions!$E$34 | C10: =-(C4+C5+C6)*Assumptions!$E$34 | D10: =-(D4+D5+D6)*Assumptions!$E$34 | E10: =-(E4+E5+E6)*Assumptions!$E$34 | F10: =-(F4+F5+F6)*Assumptions!$E$34 | G10: =-(G4+G5+G6)*Assumptions!$E$34 | H10: =-(H4+H5+H6)*Assumptions!$E$34 | I10: =-(I4+I5+I6)*Assumptions!$E$34 | ... AK10: =-(AK4+AK5+AK6)*Assumptions!$E$34
A11: Less: Stripe fees (school) | B11: =-B7*Assumptions!$E$35 | C11: =-C7*Assumptions!$E$35 | D11: =-D7*Assumptions!$E$35 | E11: =-E7*Assumptions!$E$35 | F11: =-F7*Assumptions!$E$35 | G11: =-G7*Assumptions!$E$35 | H11: =-H7*Assumptions!$E$35 | I11: =-I7*Assumptions!$E$35 | ... AK11: =-AK7*Assumptions!$E$35
A13: NET REVENUE | B13: =B9+B10+B11 | C13: =C9+C10+C11 | D13: =D9+D10+D11 | E13: =E9+E10+E11 | F13: =F9+F10+F11 | G13: =G9+G10+G11 | H13: =H9+H10+H11 | I13: =I9+I10+I11 | ... AK13: =AK9+AK10+AK11

Sheet Costs
A1: COSTS (USD)
A3: Cost line | B3: M1 | C3: M2 | D3: M3 | E3: M4 | F3: M5 | G3: M6 | H3: M7 | I3: M8 | J3: M9 | K3: M10 | L3: M11 | M3: M12 | N3: M13 | O3: M14 | P3: M15 | Q3: M16 | R3: M17 | S3: M18 | T3: M19 | U3: M20 | V3: M21 | W3: M22 | X3: M23 | Y3: M24 | Z3: M25 | AA3: M26 | AB3: M27 | AC3: M28 | AD3: M29 | AE3: M30 | AF3: M31 | AG3: M32 | AH3: M33 | AI3: M34 | AJ3: M35 | AK3: M36
A4: One-off: App dev | B4: =IF(1=1,Assumptions!$E$47,0) | C4: =IF(2=1,Assumptions!$E$47,0) | D4: =IF(3=1,Assumptions!$E$47,0) | E4: =IF(4=1,Assumptions!$E$47,0) | F4: =IF(5=1,Assumptions!$E$47,0) | G4: =IF(6=1,Assumptions!$E$47,0) | H4: =IF(7=1,Assumptions!$E$47,0) | I4: =IF(8=1,Assumptions!$E$47,0) | J4: =IF(9=1,Assumptions!$E$47,0) | K4: =IF(10=1,Assumptions!$E$47,0) | L4: =IF(11=1,Assumptions!$E$47,0) | M4: =IF(12=1,Assumptions!$E$47,0) | N4: =IF(13=1,Assumptions!$E$47,0) | O4: =IF(14=1,Assumptions!$E$47,0) | P4: =IF(15=1,Assumptions!$E$47,0) | Q4: =IF(16=1,Assumptions!$E$47,0) | R4: =IF(17=1,Assumptions!$E$47,0) | S4: =IF(18=1,Assumptions!$E$47,0) | T4: =IF(19=1,Assumptions!$E$47,0) | U4: =IF(20=1,Assumptions!$E$47,0) | V4: =IF(21=1,Assumptions!$E$47,0) | W4: =IF(22=1,Assumptions!$E$47,0) | X4: =IF(23=1,Assumptions!$E$47,0) | Y4: =IF(24=1,Assumptions!$E$47,0) | Z4: =IF(25=1,Assumptions!$E$47,0) | AA4: =IF(26=1,Assumptions!$E$47,0) | AB4: =IF(27=1,Assumptions!$E$47,0) | AC4: =IF(28=1,Assumptions!$E$47,0) | AD4: =IF(29=1,Assumptions!$E$47,0) | AE4: =IF(30=1,Assumptions!$E$47,0) | AF4: =IF(31=1,Assumptions!$E$47,0) | AG4: =IF(32=1,Assumptions!$E$47,0) | AH4: =IF(33=1,Assumptions!$E$47,0) | AI4: =IF(34=1,Assumptions!$E$47,0) | AJ4: =IF(35=1,Assumptions!$E$47,0) | AK4: =IF(36=1,Assumptions!$E$47,0)
A5: One-off: Content | B5: =IF(1=1,Assumptions!$E$48,0) | C5: =IF(2=1,Assumptions!$E$48,0) | D5: =IF(3=1,Assumptions!$E$48,0) | E5: =IF(4=1,Assumptions!$E$48,0) | F5: =IF(5=1,Assumptions!$E$48,0) | G5: =IF(6=1,Assumptions!$E$48,0) | H5: =IF(7=1,Assumptions!$E$48,0) | I5: =IF(8=1,Assumptions!$E$48,0) | J5: =IF(9=1,Assumptions!$E$48,0) | K5: =IF(10=1,Assumptions!$E$48,0) | L5: =IF(11=1,Assumptions!$E$48,0) | M5: =IF(12=1,Assumptions!$E$48,0) | N5: =IF(13=1,Assumptions!$E$48,0) | O5: =IF(14=1,Assumptions!$E$48,0) | P5: =IF(15=1,Assumptions!$E$48,0) | Q5: =IF(16=1,Assumptions!$E$48,0) | R5: =IF(17=1,Assumptions!$E$48,0) | S5: =IF(18=1,Assumptions!$E$48,0) | T5: =IF(19=1,Assumptions!$E$48,0) | U5: =IF(20=1,Assumptions!$E$48,0) | V5: =IF(21=1,Assumptions!$E$48,0) | W5: =IF(22=1,Assumptions!$E$48,0) | X5: =IF(23=1,Assumptions!$E$48,0) | Y5: =IF(24=1,Assumptions!$E$48,0) | Z5: =IF(25=1,Assumptions!$E$48,0) | AA5: =IF(26=1,Assumptions!$E$48,0) | AB5: =IF(27=1,Assumptions!$E$48,0) | AC5: =IF(28=1,Assumptions!$E$48,0) | AD5: =IF(29=1,Assumptions!$E$48,0) | AE5: =IF(30=1,Assumptions!$E$48,0) | AF5: =IF(31=1,Assumptions!$E$48,0) | AG5: =IF(32=1,Assumptions!$E$48,0) | AH5: =IF(33=1,Assumptions!$E$48,0) | AI5: =IF(34=1,Assumptions!$E$48,0) | AJ5: =IF(35=1,Assumptions!$E$48,0) | AK5: =IF(36=1,Assumptions!$E$48,0)
A6: One-off: Branding | B6: =IF(1=1,Assumptions!$E$50,0) | C6: =IF(2=1,Assumptions!$E$50,0) | D6: =IF(3=1,Assumptions!$E$50,0) | E6: =IF(4=1,Assumptions!$E$50,0) | F6: =IF(5=1,Assumptions!$E$50,0) | G6: =IF(6=1,Assumptions!$E$50,0) | H6: =IF(7=1,Assumptions!$E$50,0) | I6: =IF(8=1,Assumptions!$E$50,0) | J6: =IF(9=1,Assumptions!$E$50,0) | K6: =IF(10=1,Assumptions!$E$50,0) | L6: =IF(11=1,Assumptions!$E$50,0) | M6: =IF(12=1,Assumptions!$E$50,0) | N6: =IF(13=1,Assumptions!$E$50,0) | O6: =IF(14=1,Assumptions!$E$50,0) | P6: =IF(15=1,Assumptions!$E$50,0) | Q6: =IF(16=1,Assumptions!$E$50,0) | R6: =IF(17=1,Assumptions!$E$50,0) | S6: =IF(18=1,Assumptions!$E$50,0) | T6: =IF(19=1,Assumptions!$E$50,0) | U6: =IF(20=1,Assumptions!$E$50,0) | V6: =IF(21=1,Assumptions!$E$50,0) | W6: =IF(22=1,Assumptions!$E$50,0) | X6: =IF(23=1,Assumptions!$E$50,0) | Y6: =IF(24=1,Assumptions!$E$50,0) | Z6: =IF(25=1,Assumptions!$E$50,0) | AA6: =IF(26=1,Assumptions!$E$50,0) | AB6: =IF(27=1,Assumptions!$E$50,0) | AC6: =IF(28=1,Assumptions!$E$50,0) | AD6: =IF(29=1,Assumptions!$E$50,0) | AE6: =IF(30=1,Assumptions!$E$50,0) | AF6: =IF(31=1,Assumptions!$E$50,0) | AG6: =IF(32=1,Assumptions!$E$50,0) | AH6: =IF(33=1,Assumptions!$E$50,0) | AI6: =IF(34=1,Assumptions!$E$50,0) | AJ6: =IF(35=1,Assumptions!$E$50,0) | AK6: =IF(36=1,Assumptions!$E$50,0)
A7: One-off: Dev accounts | B7: =IF(1=1,Assumptions!$E$49,0) | C7: =IF(2=1,Assumptions!$E$49,0) | D7: =IF(3=1,Assumptions!$E$49,0) | E7: =IF(4=1,Assumptions!$E$49,0) | F7: =IF(5=1,Assumptions!$E$49,0) | G7: =IF(6=1,Assumptions!$E$49,0) | H7: =IF(7=1,Assumptions!$E$49,0) | I7: =IF(8=1,Assumptions!$E$49,0) | J7: =IF(9=1,Assumptions!$E$49,0) | K7: =IF(10=1,Assumptions!$E$49,0) | L7: =IF(11=1,Assumptions!$E$49,0) | M7: =IF(12=1,Assumptions!$E$49,0) | N7: =IF(13=1,Assumptions!$E$49,0) | O7: =IF(14=1,Assumptions!$E$49,0) | P7: =IF(15=1,Assumptions!$E$49,0) | Q7: =IF(16=1,Assumptions!$E$49,0) | R7: =IF(17=1,Assumptions!$E$49,0) | S7: =IF(18=1,Assumptions!$E$49,0) | T7: =IF(19=1,Assumptions!$E$49,0) | U7: =IF(20=1,Assumptions!$E$49,0) | V7: =IF(21=1,Assumptions!$E$49,0) | W7: =IF(22=1,Assumptions!$E$49,0) | X7: =IF(23=1,Assumptions!$E$49,0) | Y7: =IF(24=1,Assumptions!$E$49,0) | Z7: =IF(25=1,Assumptions!$E$49,0) | AA7: =IF(26=1,Assumptions!$E$49,0) | AB7: =IF(27=1,Assumptions!$E$49,0) | AC7: =IF(28=1,Assumptions!$E$49,0) | AD7: =IF(29=1,Assumptions!$E$49,0) | AE7: =IF(30=1,Assumptions!$E$49,0) | AF7: =IF(31=1,Assumptions!$E$49,0) | AG7: =IF(32=1,Assumptions!$E$49,0) | AH7: =IF(33=1,Assumptions!$E$49,0) | AI7: =IF(34=1,Assumptions!$E$49,0) | AJ7: =IF(35=1,Assumptions!$E$49,0) | AK7: =IF(36=1,Assumptions!$E$49,0)
A9: Hosting | B9: =Users!B21/1000*Assumptions!$E$36 | C9: =Users!C21/1000*Assumptions!$E$36 | D9: =Users!D21/1000*Assumptions!$E$36 | E9: =Users!E21/1000*Assumptions!$E$36 | F9: =Users!F21/1000*Assumptions!$E$36 | G9: =Users!G21/1000*Assumptions!$E$36 | H9: =Users!H21/1000*Assumptions!$E$36 | I9: =Users!I21/1000*Assumptions!$E$36 | ... AK9: =Users!AK21/1000*Assumptions!$E$36
A10: Content licences | B10: =Assumptions!$E$37 | C10: =Assumptions!$E$37 | D10: =Assumptions!$E$37 | E10: =Assumptions!$E$37 | F10: =Assumptions!$E$37 | G10: =Assumptions!$E$37 | H10: =Assumptions!$E$37 | I10: =Assumptions!$E$37 | ... AK10: =Assumptions!$E$37
A11: Paid marketing | B11: =IF(1<3,0,Assumptions!$E$9) | C11: =IF(2<3,0,Assumptions!$E$9) | D11: =IF(3<3,0,Assumptions!$E$9) | E11: =IF(4<3,0,Assumptions!$E$9) | F11: =IF(5<3,0,Assumptions!$E$9) | G11: =IF(6<3,0,Assumptions!$E$9) | H11: =IF(7<3,0,Assumptions!$E$9) | I11: =IF(8<3,0,Assumptions!$E$9) | J11: =IF(9<3,0,Assumptions!$E$9) | K11: =IF(10<3,0,Assumptions!$E$9) | L11: =IF(11<3,0,Assumptions!$E$9) | M11: =IF(12<3,0,Assumptions!$E$9) | N11: =IF(13<3,0,Assumptions!$E$9) | O11: =IF(14<3,0,Assumptions!$E$9) | P11: =IF(15<3,0,Assumptions!$E$9) | Q11: =IF(16<3,0,Assumptions!$E$9) | R11: =IF(17<3,0,Assumptions!$E$9) | S11: =IF(18<3,0,Assumptions!$E$9) | T11: =IF(19<3,0,Assumptions!$E$9) | U11: =IF(20<3,0,Assumptions!$E$9) | V11: =IF(21<3,0,Assumptions!$E$9) | W11: =IF(22<3,0,Assumptions!$E$9) | X11: =IF(23<3,0,Assumptions!$E$9) | Y11: =IF(24<3,0,Assumptions!$E$9) | Z11: =IF(25<3,0,Assumptions!$E$9) | AA11: =IF(26<3,0,Assumptions!$E$9) | AB11: =IF(27<3,0,Assumptions!$E$9) | AC11: =IF(28<3,0,Assumptions!$E$9) | AD11: =IF(29<3,0,Assumptions!$E$9) | AE11: =IF(30<3,0,Assumptions!$E$9) | AF11: =IF(31<3,0,Assumptions!$E$9) | AG11: =IF(32<3,0,Assumptions!$E$9) | AH11: =IF(33<3,0,Assumptions!$E$9) | AI11: =IF(34<3,0,Assumptions!$E$9) | AJ11: =IF(35<3,0,Assumptions!$E$9) | AK11: =IF(36<3,0,Assumptions!$E$9)
A13: Founder salary | B13: =Assumptions!$E$40 | C13: =Assumptions!$E$40 | D13: =Assumptions!$E$40 | E13: =Assumptions!$E$40 | F13: =Assumptions!$E$40 | G13: =Assumptions!$E$40 | H13: =Assumptions!$E$40 | I13: =Assumptions!$E$40 | ... AK13: =Assumptions!$E$40
A14: Contractors | B14: =Assumptions!$E$41 | C14: =Assumptions!$E$41 | D14: =Assumptions!$E$41 | E14: =Assumptions!$E$41 | F14: =Assumptions!$E$41 | G14: =Assumptions!$E$41 | H14: =Assumptions!$E$41 | I14: =Assumptions!$E$41 | ... AK14: =Assumptions!$E$41
A15: Tools & subs | B15: =Assumptions!$E$42 | C15: =Assumptions!$E$42 | D15: =Assumptions!$E$42 | E15: =Assumptions!$E$42 | F15: =Assumptions!$E$42 | G15: =Assumptions!$E$42 | H15: =Assumptions!$E$42 | I15: =Assumptions!$E$42 | ... AK15: =Assumptions!$E$42
A16: Legal/compliance | B16: =Assumptions!$E$43 | C16: =Assumptions!$E$43 | D16: =Assumptions!$E$43 | E16: =Assumptions!$E$43 | F16: =Assumptions!$E$43 | G16: =Assumptions!$E$43 | H16: =Assumptions!$E$43 | I16: =Assumptions!$E$43 | ... AK16: =Assumptions!$E$43
A17: Insurance & misc | B17: =Assumptions!$E$44 | C17: =Assumptions!$E$44 | D17: =Assumptions!$E$44 | E17: =Assumptions!$E$44 | F17: =Assumptions!$E$44 | G17: =Assumptions!$E$44 | H17: =Assumptions!$E$44 | I17: =Assumptions!$E$44 | ... AK17: =Assumptions!$E$44
A19: TOTAL COSTS | B19: =SUM(B4:B7)+SUM(B9:B11)+SUM(B13:B17) | C19: =SUM(C4:C7)+SUM(C9:C11)+SUM(C13:C17) | D19: =SUM(D4:D7)+SUM(D9:D11)+SUM(D13:D17) | E19: =SUM(E4:E7)+SUM(E9:E11)+SUM(E13:E17) | F19: =SUM(F4:F7)+SUM(F9:F11)+SUM(F13:F17) | G19: =SUM(G4:G7)+SUM(G9:G11)+SUM(G13:G17) | H19: =SUM(H4:H7)+SUM(H9:H11)+SUM(H13:H17) | I19: =SUM(I4:I7)+SUM(I9:I11)+SUM(I13:I17) | ... AK19: =SUM(AK4:AK7)+SUM(AK9:AK11)+SUM(AK13:AK17)

Sheet P&L
A1: PROFIT & LOSS (USD)
A3: Line | B3: M1 | C3: M2 | D3: M3 | E3: M4 | F3: M5 | G3: M6 | H3: M7 | I3: M8 | J3: M9 | K3: M10 | L3: M11 | M3: M12 | N3: M13 | O3: M14 | P3: M15 | Q3: M16 | R3: M17 | S3: M18 | T3: M19 | U3: M20 | V3: M21 | W3: M22 | X3: M23 | Y3: M24 | Z3: M25 | AA3: M26 | AB3: M27 | AC3: M28 | AD3: M29 | AE3: M30 | AF3: M31 | AG3: M32 | AH3: M33 | AI3: M34 | AJ3: M35 | AK3: M36
A4: Net revenue | B4: =Revenue!B13 | C4: =Revenue!C13 | D4: =Revenue!D13 | E4: =Revenue!E13 | F4: =Revenue!F13 | G4: =Revenue!G13 | H4: =Revenue!H13 | I4: =Revenue!I13 | ... AK4: =Revenue!AK13
A5: Total costs | B5: =-Costs!B19 | C5: =-Costs!C19 | D5: =-Costs!D19 | E5: =-Costs!E19 | F5: =-Costs!F19 | G5: =-Costs!G19 | H5: =-Costs!H19 | I5: =-Costs!I19 | ... AK5: =-Costs!AK19
A7: EBITDA | B7: =B4+B5 | C7: =C4+C5 | D7: =D4+D5 | E7: =E4+E5 | F7: =F4+F5 | G7: =G4+G5 | H7: =H4+H5 | I7: =I4+I5 | ... AK7: =AK4+AK5
A9: Cumulative cash | B9: =B7 | C9: =B9+C7 | D9: =C9+D7 | E9: =D9+E7 | F9: =E9+F7 | G9: =F9+G7 | H9: =G9+H7 | I9: =H9+I7 | J9: =I9+J7 | ... AK9: =AJ9+AK7

Sheet Summary
A1: EXECUTIVE SUMMARY (USD)
A2: =CONCATENATE("Scenario: ",Cover!C9," | Strategy: Tight free")
A4: KEY METRICS
A5: Metric | B5: Year 1 | C5: Year 2 | D5: Year 3 | E5: Total
A6: Net revenue ($) | B6: =SUM(Revenue!B13:M13) | C6: =SUM(Revenue!N13:Y13) | D6: =SUM(Revenue!Z13:AK13) | E6: =B6+C6+D6
A7: Total costs ($) | B7: =SUM(Costs!B19:M19) | C7: =SUM(Costs!N19:Y19) | D7: =SUM(Costs!Z19:AK19) | E7: =B7+C7+D7
A8: EBITDA ($) | B8: =SUM('P&L'!B7:M7) | C8: =SUM('P&L'!N7:Y7) | D8: =SUM('P&L'!Z7:AK7) | E8: =B8+C8+D8
A10: Free users (end) | B10: =Users!M9 | C10: =Users!Y9 | D10: =Users!AK9 | E10: =D10
A11: Paid subscribers (end) | B11: =Users!M14 | C11: =Users!Y14 | D11: =Users!AK14 | E11: =D11
A12: Schools (end) | B12: =Users!M19 | C12: =Users!Y19 | D12: =Users!AK19 | E12: =D12
A14: Cumulative cash (end) | B14: ='P&L'!M9 | C14: ='P&L'!Y9 | D14: ='P&L'!AK9 | E14: =D14
A16: UNIT ECONOMICS (END Y3)
A17: ARPU (monthly, paid) | B17: =IFERROR('P&L'!AK4/Users!AK14,0)
A18: Monthly churn | B18: =Assumptions!E16
A19: LTV per paid user ($) | B19: =IFERROR(B17/B18,0)
A20: Paid CAC ($/paid install) | B20: =IFERROR(SUM(Costs!Z11:AK11)/MAX(1,SUM(Users!Z5:AK5)),0)
A21: LTV : paid CAC ratio | B21: =IFERROR(B19/B20,0)
A23: BREAK-EVEN
A24: First EBITDA-positive month | B24: =IFERROR(MATCH(TRUE(),INDEX('P&L'!B7:AK7>0,0),0),"Not in 36mo")
A25: Cash-positive month | B25: =IFERROR(MATCH(TRUE(),INDEX('P&L'!B9:AK9>0,0),0),"Not in 36mo")
A26: Peak cash burn | B26: =MIN('P&L'!B9:AK9)
A27: → Minimum funding required
A29: STRATEGY-SPECIFIC RISKS
A30: 1. Tight-free strategy: small free pool, weak App Store ranking. Mitigate with strong paid marketing.
A31: 2. Negative reviews on paywall placement are likely. Monitor App Store reviews weekly in months 1-3.
A32: 3. Reduced organic growth means CAC is the dominant lever. Test multiple ad creatives early.
A33: 4. School B2B contribution is more important here than in generous-free. Don't underinvest in sales.
A34: 5. If conversion underperforms (under 4%), revisit free/paid split before month 6.
A35: 6. Founder at zero salary (Bear) is unsustainable past 6-9 months.
